Workbook
Name AGSMS: 'Product List'!$C$2180
Name AMWTH: 'Product List'!$D$2180
Name APTOS: 'Product List'!$E$2180:$E$2182
Name ARL: 'Product List'!$F$2180:$F$2247
Name AZTCW: 'Product List'!$G$2180
Name BLINE: 'Product List'!$H$2180:$H$2185
Name BPT: 'Product List'!$I$2180:$I$2222
Name BUR: 'Product List'!$J$2180:$J$2188
Name BUSS: 'Product List'!$K$2180
Name CASOL: 'Product List'!$L$2180:$L$2185
Name CHEML: 'Product List'!$M$2180:$M$2187
Name Code: 'Product List'!$A$2180:$Y$2337
Name COND: 'Product List'!$N$2180:$N$2184
Name CONDR: 'Product List'!$O$2180:$O$2183
Name CORRUBRACKET: 'Product List'!$BX$2324:$BX$2337
Name CPAWS: 'Product List'!$P$2180:$P$2200
Name CTEED: 'Product List'!$Q$2180:$Q$2181
Name CULLY: 'Product List'!$R$2180
Name DIXTI: 'Product List'!$S$2180:$S$2181
Name DOT: 'Product List'!$T$2180:$T$2181
Name EATON: 'Product List'!$U$2180:$U$2259
Name ECOBE: 'Product List'!$V$2180
Name ECOSO: 'Product List'!$W$2180:$W$2183
Name EDF: 'Product List'!$X$2180:$X$2191
Name ENP: 'Product List'!$Y$2180:$Y$2234
Name EVRST: 'Product List'!$Z$2180:$Z$2201
Name EZSLR: 'Product List'!$AA$2180:$AA$2182
Name FAST: 'Product List'!$AB$2180:$AB$2185
Name FLEX: 'Product List'!$AC$2180:$AC$2189
Name FRANK: 'Product List'!$AD$2180:$AD$2183
Name FRZ: 'Product List'!#REF!
Name G10.C__415W_BLK_132C_32MM__32: 'Order Sheet'!$D$12
Name GALV: 'Product List'!$AE$2180:$AE$2181
Name GED: 'Product List'!$AF$2180:$AF$2187
Name GENRC: 'Product List'!$AG$2180:$AG$2204
Name GEOC: 'Product List'!$AH$2180:$AH$2183
Name GREAV: 'Product List'!$AI$2180:$AI$2182
Name HEYCO: 'Product List'!$AJ$2180:$AJ$2190
Name HYPRE: 'Product List'!#REF!
Name HYUND: 'Product List'!$AK$2180:$AK$2183
Name IDEAL: 'Product List'!$AL$2180:$AL$2193
Name ILSCO: 'Product List'!$AM$2180:$AM$2185
Name IMO: 'Product List'!$AN$2180:$AN$2181
Name IRIDG: 'Product List'!$AO$2180:$AO$2290
Name JASOL: 'Product List'!$AP$2180
Name JINKO: 'Product List'!$AQ$2180:$AQ$2183
Name KLEIN: 'Product List'!$AR$2180:$AR$2219
Name LF: 'Product List'!$AS$2180:$AS$2195
Name LFUSE: 'Product List'!$AS$2180:$AS$2200
Name LGCHE: 'Product List'!$AT$2180:$AT$2181
Name LGSOL: 'Product List'!$AU$2180:$AU$2183
Name LITHN: 'Product List'!$AV$2180:$AV$2183
Name LLH: 'Product List'!#REF!
Name LONGI: 'Product List'!$AW$2180:$AW$2181
Name LUMI: 'Product List'!$AX$2180:$AX$2181
Name MAXON: 'Product List'!$AY$2180
Name MERSN: 'Product List'!$AZ$2180:$AZ$2194
Name MIL: 'Product List'!$BA$2180:$BA$2189
Name MILW: 'Product List'!$BB$2180:$BB$2211
Name MISC.: 'Product List'!$BC$2180:$BC$2181

Sheet Sheet1
A1: LINE TYPE | B1: QUANTITY | C1: TYPE/DESIGNATION | D1: GROUP | E1: MFR | F1: PRODUCT | G1: DESCRIPTION | H1: UNIT/LOT | I1: SELL | J1: UOM | K1: COST | L1: UOM | M1: CUSTOMER PO NUMBER | N1: INTERNAL NOTES
A2: =IF(B2="","","S") -> S | B2: =IF(Worksheet!D2="","",Worksheet!D2) -> 15 | E2: =IF(Worksheet!B2="","",Worksheet!B2) -> QCELL | F2: =IF(Worksheet!C2="","",Worksheet!C2) -> Q.PEAK DUO BLK ML-G10+ 400
A3: =IF(B3="","","S") -> S | B3: =IF(Worksheet!D3="","",Worksheet!D3) -> 2 | E3: =IF(Worksheet!B3="","",Worksheet!B3) -> BPT | F3: =IF(Worksheet!C3="","",Worksheet!C3) -> 382DC
A4: =IF(B4="","","S") -> S | B4: =IF(Worksheet!D4="","",Worksheet!D4) -> 5 | E4: =IF(Worksheet!B4="","",Worksheet!B4) -> BPT | F4: =IF(Worksheet!C4="","",Worksheet!C4) -> SR075
A5: =IF(B5="","","S") -> S | B5: =IF(Worksheet!D5="","",Worksheet!D5) -> 1 | E5: =IF(Worksheet!B5="","",Worksheet!B5) -> CHEML | F5: =IF(Worksheet!C5="","",Worksheet!C5) -> F1270GR
A6: =IF(B6="","","S") -> S | B6: =IF(Worksheet!D6="","",Worksheet!D6) -> 5 | E6: =IF(Worksheet!B6="","",Worksheet!B6) -> SWIRE | F6: =IF(Worksheet!C6="","",Worksheet!C6) -> 282
A7: =IF(B7="","","S") -> S | B7: =IF(Worksheet!D7="","",Worksheet!D7) -> 4 | E7: =IF(Worksheet!B7="","",Worksheet!B7) -> SWIRE | F7: =IF(Worksheet!C7="","",Worksheet!C7) -> 452TZ
A8: =IF(B8="","","S") -> S | B8: =IF(Worksheet!D8="","",Worksheet!D8) -> 5 | E8: =IF(Worksheet!B8="","",Worksheet!B8) -> SWIRE | F8: =IF(Worksheet!C8="","",Worksheet!C8) -> 832TZ
A9: =IF(B9="","","S") -> S | B9: =IF(Worksheet!D9="","",Worksheet!D9) -> 2 | E9: =IF(Worksheet!B9="","",Worksheet!B9) -> EATON | F9: =IF(Worksheet!C9="","",Worksheet!C9) -> BR220
A10: =IF(B10="","","S") -> S | B10: =IF(Worksheet!D10="","",Worksheet!D10) -> 1 | E10: =IF(Worksheet!B10="","",Worksheet!B10) -> EATON | F10: =IF(Worksheet!C10="","",Worksheet!C10) -> DG222URB
A11: =IF(B11="","","S") -> S | B11: =IF(Worksheet!D11="","",Worksheet!D11) -> 1 | E11: =IF(Worksheet!B11="","",Worksheet!B11) -> EZSLR | F11: =IF(Worksheet!C11="","",Worksheet!C11) -> JB-1.2
A12: =IF(B12="","","S") -> S | B12: =IF(Worksheet!D12="","",Worksheet!D12) -> 100 | E12: =IF(Worksheet!B12="","",Worksheet!B12) -> FLEX | F12: =IF(Worksheet!C12="","",Worksheet!C12) -> RWA-3/4
A13: =IF(B13="","","S") -> S | B13: =IF(Worksheet!D13="","",Worksheet!D13) -> 1 | E13: =IF(Worksheet!B13="","",Worksheet!B13) -> NSI | F13: =IF(Worksheet!C13="","",Worksheet!C13) -> 11500
... A200: =IF(B200="","","S") | B200: =IF(Worksheet!D200="","",Worksheet!D200) | E200: =IF(Worksheet!B200="","",Worksheet!B200) | F200: =IF(Worksheet!C200="","",Worksheet!C200)

Sheet Order Sheet
B2: JOB NAME | C2: Davesky Aragones | E2: PO NUMBER
B3: DELIVERY ADDRESS | C3: 151 Borland St, Brooksville, FL, 34604 | E3: DELIVERY DATE
E4: INSTALLER
B5: PANEL ORIENTATION | D5: BOB/BOW OR SILVER FRAME | E5: FINANCE | F5: Palmetto
B6: Modules
B7: MFR | C7: CATALOG | D7: DESCRIPTION | E7: QTY | F7: NOTES
B8: TRINA | C8: TSM-420-NE09RC.05 | D8: 420W Trina
A9: =IF(D9="","",IFERROR(IF(E9=0,"",VLOOKUP(C9,'Product List'!B:E,4,FALSE)),"")) | B9: MISIO | C9: MSE425SX9Z | D9: =IFERROR(IF(VLOOKUP(C9,'Product List'!B:C,2,FALSE)=VLOOKUP(B9,'Product List'!$A$2179:$DE$2338,2,FALSE),IFERROR(VLOOKUP(C9,'Product List'!B:D,3,FALSE),""),""),"") -> 425W PERC 72C BLK/BLK | F9: CHANGE TO MSX10-435HN0B
B10: CASOL | C10: CS3N-395MS | D10: CANADIAN SOLAR 395
A11: =IF(D11="","",IFERROR(IF(E11=0,"",VLOOKUP(C11,'Product List'!B:E,4,FALSE)),"")) | B11: TRINA | C11: TSM-390-DE09C.07 | D11: =IFERROR(IF(VLOOKUP(C11,'Product List'!B:C,2,FALSE)=VLOOKUP(B11,'Product List'!$A$2179:$DE$2338,2,FALSE),IFERROR(VLOOKUP(C11,'Product List'!B:D,3,FALSE),""),""),"") -> VERTEX S, BOT 390W (30MM)
A12: =IF(D12="","",IFERROR(IF(E12=0,"",VLOOKUP(C12,'Product List'!B:E,4,FALSE)),"")) -> 2000000944 | B12: QCELL | C12: Q.PEAK DUO BLK ML-G10+ 400 | D12: =IFERROR(IF(VLOOKUP(C12,'Product List'!B:C,2,FALSE)=VLOOKUP(B12,'Product List'!$A$2179:$DE$2338,2,FALSE),IFERROR(VLOOKUP(C12,'Product List'!B:D,3,FALSE),""),""),"") -> G10+ 400W BLK 132C 32MM (32) | E12: 15 | F12: Q.TRON BLK M-G2.C1+ 430
A13: =IF(D13="","",IFERROR(IF(E13=0,"",VLOOKUP(C13,'Product List'!B:E,4,FALSE)),"")) | B13: SILFB | C13: SIL 370 HC | D13: =IFERROR(IF(VLOOKUP(C13,'Product List'!B:C,2,FALSE)=VLOOKUP(B13,'Product List'!$A$2179:$DE$2338,2,FALSE),IFERROR(VLOOKUP(C13,'Product List'!B:D,3,FALSE),""),""),"") -> PRIME 370 BLK 120C 35MM (26) 884
A14: =IF(D14="","",IFERROR(IF(E14=0,"",VLOOKUP(C14,'Product List'!B:E,4,FALSE)),"")) | B14: PANAS | C14: EVPV360K | D14: =IFERROR(IF(VLOOKUP(C14,'Product List'!B:C,2,FALSE)=VLOOKUP(B14,'Product List'!$A$2179:$DE$2338,2,FALSE),IFERROR(VLOOKUP(C14,'Product List'!B:D,3,FALSE),""),""),"") -> 360W BLK 120C 30MM (33) [858]
A15: =IF(D15="","",IFERROR(IF(E15=0,"",VLOOKUP(C15,'Product List'!B:E,4,FALSE)),"")) | B15: URECO | C15: FBM400MFG-BB | D15: =IFERROR(IF(VLOOKUP(C15,'Product List'!B:C,2,FALSE)=VLOOKUP(B15,'Product List'!$A$2179:$DE$2338,2,FALSE),IFERROR(VLOOKUP(C15,'Product List'!B:D,3,FALSE),""),""),"") -> 400W BLK 108C 35MM (31) [806]
A16: =IF(D16="","",IFERROR(IF(E16=0,"",VLOOKUP(C16,'Product List'!B:E,4,FALSE)),"")) | B16: RECSO | C16: REC400AA PURE | D16: =IFERROR(IF(VLOOKUP(C16,'Product List'!B:C,2,FALSE)=VLOOKUP(B16,'Product List'!$A$2179:$DE$2338,2,FALSE),IFERROR(VLOOKUP(C16,'Product List'!B:D,3,FALSE),""),""),"") -> ALPHA 400W BLK 66C HJT 30MM (33)
A17: =IF(D17="","",IFERROR(IF(E17=0,"",VLOOKUP(C17,'Product List'!B:E,4,FALSE)),"")) | B17: VSUN | C17: VSUN370-120BMH | D17: =IFERROR(IF(VLOOKUP(C17,'Product List'!B:C,2,FALSE)=VLOOKUP(B17,'Product List'!$A$2179:$DE$2338,2,FALSE),IFERROR(VLOOKUP(C17,'Product List'!B:D,3,FALSE),""),""),"") -> 370W 120 HC BLK | F17: ****Shop Stock*****
A18: =IF(D18="","",IFERROR(IF(E18=0,"",VLOOKUP(C18,'Product List'!B:E,4,FALSE)),"")) | B18: VSUN | C18: VSUN450-144BMH-DG | D18: =IFERROR(IF(VLOOKUP(C18,'Product List'!B:C,2,FALSE)=VLOOKUP(B18,'Product List'!$A$2179:$DE$2338,2,FALSE),IFERROR(VLOOKUP(C18,'Product List'!B:D,3,FALSE),""),""),"") -> 450W BIFACIAL
A19: =IF(D19="","",IFERROR(IF(E19=0,"",VLOOKUP(C19,'Product List'!B:E,4,FALSE)),"")) | B19: Inverters and Batteries
A20: =IF(D20="","",IFERROR(IF(E20=0,"",VLOOKUP(C20,'Product List'!B:E,4,FALSE)),"")) | B20: MFR | C20: CATALOG | D20: DESCRIPTION | E20: QTY | F20: NOTES
A21: =IF(D21="","",IFERROR(IF(E21=0,"",VLOOKUP(C21,'Product List'!B:E,4,FALSE)),"")) | B21: QCELL | D21: Q.MI.349B-G1 | E21: 15 | F21: Q.MI.349B-G1 QCELL MICROINVERTER
A22: =IF(D22="","",IFERROR(IF(E22=0,"",VLOOKUP(C22,'Product List'!B:E,4,FALSE)),"")) | B22: QCELL | D22: SPCD-00001 | E22: 1 | F22: Q.Home Combiner 80 G1
A23: =IF(D23="","",IFERROR(IF(E23=0,"",VLOOKUP(C23,'Product List'!B:E,4,FALSE)),"")) | B23: QCELL | D23: SBED-00046 | E23: 1 | F23: LTE-MT-MODEM CAT4-TN5 CELL MODEM
A24: =IF(D24="","",IFERROR(IF(E24=0,"",VLOOKUP(C24,'Product List'!B:E,4,FALSE)),"")) | B24: QCELL | D24: CAS-HQ-LO-1000 | E24: 15 | F24: QCELL AC CABLE LANDSCAPE
A25: =IF(D25="","",IFERROR(IF(E25=0,"",VLOOKUP(C25,'Product List'!B:E,4,FALSE)),"")) | B25: QCELL | D25: CAB-HQ-KIT-200 | E25: 30 | F25: QCELL RAW CABLE
A26: =IF(D26="","",IFERROR(IF(E26=0,"",VLOOKUP(C26,'Product List'!B:E,4,FALSE)),"")) | B26: QCELL | D26: CON-HQ-KIT-20 | E26: 1 | F26: QCELL AC FIELD WIREABLE SET M/F
A27: =IF(D27="","",IFERROR(IF(E27=0,"",VLOOKUP(C27,'Product List'!B:E,4,FALSE)),"")) | B27: QCELL | D27: ECAP-HQ-KIT-20 | E27: 3 | F27: QCELL AC CABLE TERM CAP
A28: =IF(D28="","",IFERROR(IF(E28=0,"",VLOOKUP(C28,'Product List'!B:E,4,FALSE)),"")) | B28: QCELL | D28: QHOME PRODUCTION CT | F28: CT-HQ-SOLID-200A-2 m
A29: =IF(D29="","",IFERROR(IF(E29=0,"",VLOOKUP(C29,'Product List'!B:E,4,FALSE)),"")) | C29: ENV-IQ-AM1-240
A30: =IF(D30="","",IFERROR(IF(E30=0,"",VLOOKUP(C30,'Product List'!B:E,4,FALSE)),"")) | C30: SN20-60MBE-330V | D30: =IFERROR(IF(VLOOKUP(C30,'Product List'!B:C,2,FALSE)=VLOOKUP(B30,'Product List'!$A$2179:$DE$2338,2,FALSE),IFERROR(VLOOKUP(C30,'Product List'!B:D,3,FALSE),""),""),"")
A31: =IF(D31="","",IFERROR(IF(E31=0,"",VLOOKUP(C31,'Product List'!B:E,4,FALSE)),"")) | B31: SOLED | C31: S440 | D31: =IFERROR(IF(VLOOKUP(C31,'Product List'!B:C,2,FALSE)=VLOOKUP(B31,'Product List'!$A$2179:$DE$2338,2,FALSE),IFERROR(VLOOKUP(C31,'Product List'!B:D,3,FALSE),""),""),"") -> 440W 60VOC 14.5ISC | F31: Swap For U650
A32: =IF(D32="","",IFERROR(IF(E32=0,"",VLOOKUP(C32,'Product List'!B:E,4,FALSE)),"")) | B32: SOLED | C32: CELL-B-R05-US-S-S2 | D32: =IFERROR(IF(VLOOKUP(C32,'Product List'!B:C,2,FALSE)=VLOOKUP(B32,'Product List'!$A$2179:$DE$2338,2,FALSE),IFERROR(VLOOKUP(C32,'Product List'!B:D,3,FALSE),""),""),"") -> CELLULAR MODEM, 5 YR PLAN (14)
A33: =IF(D33="","",IFERROR(IF(E33=0,"",VLOOKUP(C33,'Product List'!B:E,4,FALSE)),"")) | B33: MULTI | C33: 32.0016P0001-UR | D33: =IFERROR(IF(VLOOKUP(C33,'Product List'!B:C,2,FALSE)=VLOOKUP(B33,'Product List'!$A$2179:$DE$2338,2,FALSE),IFERROR(VLOOKUP(C33,'Product List'!B:D,3,FALSE),""),""),"") -> FEMALE MC4, 10AWG (CONN W/ PIN)
A34: =IF(D34="","",IFERROR(IF(E34=0,"",VLOOKUP(C34,'Product List'!B:E,4,FALSE)),"")) | B34: MULTI | C34: 32.0017P0001-UR | D34: =IFERROR(IF(VLOOKUP(C34,'Product List'!B:C,2,FALSE)=VLOOKUP(B34,'Product List'!$A$2179:$DE$2338,2,FALSE),IFERROR(VLOOKUP(C34,'Product List'!B:D,3,FALSE),""),""),"") -> MALE MC4, 10AWG (CONN W/PIN)
A35: =IF(D35="","",IFERROR(IF(E35=0,"",VLOOKUP(C35,'Product List'!B:E,4,FALSE)),"")) | B35: SOLED | C35: SE11400H-US000BEU4 | D35: =IFERROR(IF(VLOOKUP(C35,'Product List'!B:C,2,FALSE)=VLOOKUP(B35,'Product List'!$A$2179:$DE$2338,2,FALSE),IFERROR(VLOOKUP(C35,'Product List'!B:D,3,FALSE),""),""),"") -> SET-APP 11.4 KW HD WAVE | F35: Swap for DCA USE11400H-USSKBEZ8
A36: =IF(D36="","",IFERROR(IF(E36=0,"",VLOOKUP(C36,'Product List'!B:E,4,FALSE)),"")) | B36: SOLED | C36: SE10000H-US000BEU4 | D36: =IFERROR(IF(VLOOKUP(C36,'Product List'!B:C,2,FALSE)=VLOOKUP(B36,'Product List'!$A$2179:$DE$2338,2,FALSE),IFERROR(VLOOKUP(C36,'Product List'!B:D,3,FALSE),""),""),"") -> SNGL PH INVTR W/HD-WAVE TECH,10.0
A37: =IF(D37="","",IFERROR(IF(E37=0,"",VLOOKUP(C37,'Product List'!B:E,4,FALSE)),"")) | B37: SOLED | C37: SE7600H-US000BEU4 | D37: =IFERROR(IF(VLOOKUP(C37,'Product List'!B:C,2,FALSE)=VLOOKUP(B37,'Product List'!$A$2179:$DE$2338,2,FALSE),IFERROR(VLOOKUP(C37,'Product List'!B:D,3,FALSE),""),""),"") -> 1 PH INVTR W/HD-WAVE TECHNLGY,7.6
A38: =IF(D38="","",IFERROR(IF(E38=0,"",VLOOKUP(C38,'Product List'!B:E,4,FALSE)),"")) | B38: SOLED | C38: SE6000H-US000BEU4 | D38: =IFERROR(IF(VLOOKUP(C38,'Product List'!B:C,2,FALSE)=VLOOKUP(B38,'Product List'!$A$2179:$DE$2338,2,FALSE),IFERROR(VLOOKUP(C38,'Product List'!B:D,3,FALSE),""),""),"") -> SNGL PHASE INVTR HD WAVE, 6.0K
A39: =IF(D39="","",IFERROR(IF(E39=0,"",VLOOKUP(C39,'Product List'!B:E,4,FALSE)),"")) | B39: SOLED | C39: SE5000H-US000BEU4 | D39: =IFERROR(IF(VLOOKUP(C39,'Product List'!B:C,2,FALSE)=VLOOKUP(B39,'Product List'!$A$2179:$DE$2338,2,FALSE),IFERROR(VLOOKUP(C39,'Product List'!B:D,3,FALSE),""),""),"") -> SNGL PH INVTR W/HD-WAVE TECH,1
A40: =IF(D40="","",IFERROR(IF(E40=0,"",VLOOKUP(C40,'Product List'!B:E,4,FALSE)),"")) | B40: SOLED | C40: SE3800H-US000BNU4 | D40: =IFERROR(IF(VLOOKUP(C40,'Product List'!B:C,2,FALSE)=VLOOKUP(B40,'Product List'!$A$2179:$DE$2338,2,FALSE),IFERROR(VLOOKUP(C40,'Product List'!B:D,3,FALSE),""),""),"") -> SET-APP 3.8KW HD WAVE
A41: =IF(D41="","",IFERROR(IF(E41=0,"",VLOOKUP(C41,'Product List'!B:E,4,FALSE)),"")) | B41: Racking
...

Sheet Product List
A1: MfrCode | B1: CatalogNo | C1: MfrCode | D1: Description | E1: Sequence | F1: Area | G1: Row | H1: Bay | I1: Shelf | J1: Default | L1: Notes | M1: Minimum QTY | N1: Divisible | O1: Price
F2: 1000000000 | G2: 10000000 | H2: 100000 | I2: 10000
A3: AGSMS | B3: OT-MOD3-1550 | C3: AGSMS | D3: GRND SCRW 61" X 4" (IRIDG 3" GM) | E3: =IF(F3="",J3,IF(G3="",F3*$F$2+K3,IF(H3="",F3*$F$2+G3*$G$2+K3,IF(I3="",F3*$F$2+G3*$G$2+H3*$H$2+K3,F3*$F$2+G3*$G$2+H3*$H$2+I3*$I$2+K3)))) -> 4000000000 | F3: 4 | J3: 20000000001
A4: AMWTH | B4: HPHE-102-50H-045DVN | C4: AMWTH | D4: PROLINE XE HYBRID 50GAL WATER HTR | E4: =IF(F4="",J4,IF(G4="",F4*$F$2+K4,IF(H4="",F4*$F$2+G4*$G$2+K4,IF(I4="",F4*$F$2+G4*$G$2+H4*$H$2+K4,F4*$F$2+G4*$G$2+H4*$H$2+I4*$I$2+K4)))) -> 4000000001 | F4: 4 | J4: 20000000001 | K4: 1
A5: APTOS | B5: DNA-120-BF10-440W | C5: APTOS | D5: 440W 120C BIFACIAL | E5: =IF(F5="",J5,IF(G5="",F5*$F$2+K5,IF(H5="",F5*$F$2+G5*$G$2+K5,IF(I5="",F5*$F$2+G5*$G$2+H5*$H$2+K5,F5*$F$2+G5*$G$2+H5*$H$2+I5*$I$2+K5)))) -> 2000000002 | F5: 2 | J5: =J4+1 -> 20000000002 | K5: 2
A6: APTOS | B6: DNA-120-MF26-370W | C6: APTOS | D6: 370W BLK 120C 35MM (26) [806] | E6: =IF(F6="",J6,IF(G6="",F6*$F$2+K6,IF(H6="",F6*$F$2+G6*$G$2+K6,IF(I6="",F6*$F$2+G6*$G$2+H6*$H$2+K6,F6*$F$2+G6*$G$2+H6*$H$2+I6*$I$2+K6)))) -> 2000000003 | F6: 2 | J6: =J5+1 -> 20000000003 | K6: 3
A7: APTOS | B7: DNA-144-BF26-440W | C7: APTOS | D7: 440W BLACK BIF (31) [682] | E7: =IF(F7="",J7,IF(G7="",F7*$F$2+K7,IF(H7="",F7*$F$2+G7*$G$2+K7,IF(I7="",F7*$F$2+G7*$G$2+H7*$H$2+K7,F7*$F$2+G7*$G$2+H7*$H$2+I7*$I$2+K7)))) -> 2000000004 | F7: 2 | J7: =J6+1 -> 20000000004 | K7: 4
A8: ARL | B8: 2010 | C8: ARL | D8: 3/4 CONDUIT HANGER W/BOLT | E8: =IF(F8="",J8,IF(G8="",F8*$F$2+K8,IF(H8="",F8*$F$2+G8*$G$2+K8,IF(I8="",F8*$F$2+G8*$G$2+H8*$H$2+K8,F8*$F$2+G8*$G$2+H8*$H$2+I8*$I$2+K8)))) -> 4000000005 | F8: 4 | J8: =J7+1 -> 20000000005 | K8: 5
A9: ARL | B9: 2020 | C9: ARL | D9: 1-IN COND HANGER W/BOLT | E9: =IF(F9="",J9,IF(G9="",F9*$F$2+K9,IF(H9="",F9*$F$2+G9*$G$2+K9,IF(I9="",F9*$F$2+G9*$G$2+H9*$H$2+K9,F9*$F$2+G9*$G$2+H9*$H$2+I9*$I$2+K9)))) -> 4000000006 | F9: 4 | J9: =J8+1 -> 20000000006 | K9: 6
A10: ARL | B10: 311 | C10: ARL | D10: 1/4 1H STL BX AC/MC STRAP 100/BX | E10: =IF(F10="",J10,IF(G10="",F10*$F$2+K10,IF(H10="",F10*$F$2+G10*$G$2+K10,IF(I10="",F10*$F$2+G10*$G$2+H10*$H$2+K10,F10*$F$2+G10*$G$2+H10*$H$2+I10*$I$2+K10)))) -> 4000000007 | F10: 4 | J10: =J9+1 -> 20000000007 | K10: 7
A11: ARL | B11: 340 | C11: ARL | D11: 1/2 1H STEEL COND STRAP | E11: =IF(F11="",J11,IF(G11="",F11*$F$2+K11,IF(H11="",F11*$F$2+G11*$G$2+K11,IF(I11="",F11*$F$2+G11*$G$2+H11*$H$2+K11,F11*$F$2+G11*$G$2+H11*$H$2+I11*$I$2+K11)))) -> 4000000008 | F11: 4 | J11: =J10+1 -> 20000000008 | K11: 8
A12: ARL | B12: 341 | C12: ARL | D12: 3/4 1H STEEL COND STRAP | E12: =IF(F12="",J12,IF(G12="",F12*$F$2+K12,IF(H12="",F12*$F$2+G12*$G$2+K12,IF(I12="",F12*$F$2+G12*$G$2+H12*$H$2+K12,F12*$F$2+G12*$G$2+H12*$H$2+I12*$I$2+K12)))) -> 4000000009 | F12: 4 | J12: =J11+1 -> 20000000009 | K12: 9
A13: ARL | B13: 342 | C13: ARL | D13: 1-IN 1H STEEL COND STRAP | E13: =IF(F13="",J13,IF(G13="",F13*$F$2+K13,IF(H13="",F13*$F$2+G13*$G$2+K13,IF(I13="",F13*$F$2+G13*$G$2+H13*$H$2+K13,F13*$F$2+G13*$G$2+H13*$H$2+I13*$I$2+K13)))) -> 4000000010 | F13: 4 | J13: =J12+1 -> 20000000010 | K13: 10
A14: ARL | B14: 350 | C14: ARL | D14: 1/2 2H STEEL COND STRAP | E14: =IF(F14="",J14,IF(G14="",F14*$F$2+K14,IF(H14="",F14*$F$2+G14*$G$2+K14,IF(I14="",F14*$F$2+G14*$G$2+H14*$H$2+K14,F14*$F$2+G14*$G$2+H14*$H$2+I14*$I$2+K14)))) -> 4000000011 | F14: 4 | J14: =J13+1 -> 20000000011 | K14: 11
A15: ARL | B15: 355 | C15: ARL | D15: 2-IN 2H STEEL COND STRAP | E15: =IF(F15="",J15,IF(G15="",F15*$F$2+K15,IF(H15="",F15*$F$2+G15*$G$2+K15,IF(I15="",F15*$F$2+G15*$G$2+H15*$H$2+K15,F15*$F$2+G15*$G$2+H15*$H$2+I15*$I$2+K15)))) -> 4000000012 | F15: 4 | J15: =J14+1 -> 20000000012 | K15: 12
A16: ARL | B16: 371 | C16: ARL | D16: 3/4 1H STL EMT STRAP | E16: =IF(F16="",J16,IF(G16="",F16*$F$2+K16,IF(H16="",F16*$F$2+G16*$G$2+K16,IF(I16="",F16*$F$2+G16*$G$2+H16*$H$2+K16,F16*$F$2+G16*$G$2+H16*$H$2+I16*$I$2+K16)))) -> 4000000013 | F16: 4 | J16: =J15+1 -> 20000000013 | K16: 13
A17: ARL | B17: 373 | C17: ARL | D17: 1-1/4 1H STL EMT STRAP | E17: =IF(F17="",J17,IF(G17="",F17*$F$2+K17,IF(H17="",F17*$F$2+G17*$G$2+K17,IF(I17="",F17*$F$2+G17*$G$2+H17*$H$2+K17,F17*$F$2+G17*$G$2+H17*$H$2+I17*$I$2+K17)))) -> 4000000014 | F17: 4 | J17: =J16+1 -> 20000000014 | K17: 14
A18: ARL | B18: 404 | C18: ARL | D18: 1-1/4 STEEL LOCKNUT | E18: =IF(F18="",J18,IF(G18="",F18*$F$2+K18,IF(H18="",F18*$F$2+G18*$G$2+K18,IF(I18="",F18*$F$2+G18*$G$2+H18*$H$2+K18,F18*$F$2+G18*$G$2+H18*$H$2+I18*$I$2+K18)))) -> 4000000015 | F18: 4 | J18: =J17+1 -> 20000000015 | K18: 15
A19: ARL | B19: 406 | C19: ARL | D19: 2-IN STEEL LOCKNUT | E19: =IF(F19="",J19,IF(G19="",F19*$F$2+K19,IF(H19="",F19*$F$2+G19*$G$2+K19,IF(I19="",F19*$F$2+G19*$G$2+H19*$H$2+K19,F19*$F$2+G19*$G$2+H19*$H$2+I19*$I$2+K19)))) -> 4000000016 | F19: 4 | J19: =J18+1 -> 20000000016 | K19: 16
... A31: ARL | B31: 522 | C31: ARL | D31: 3/4X1/2 RED BUSH | E31: =IF(F31="",J31,IF(G31="",F31*$F$2+K31,IF(H31="",F31*$F$2+G31*$G$2+K31,IF(I31="",F31*$F$2+G31*$G$2+H31*$H$2+K31,F31*$F$2+G31*$G$2+H31*$H$2+I31*$I$2+K31)))) -> 4000000028 | F31: 4 | J31: =J30+1 -> 20000000028 | K31: 28
A32: ARL | B32: 6A3 | C32: ARL | D32: 3/4 D/C OFFSET NIPPLE | E32: =IF(F32="",J32,IF(G32="",F32*$F$2+K32,IF(H32="",F32*$F$2+G32*$G$2+K32,IF(I32="",F32*$F$2+G32*$G$2+H32*$H$2+K32,F32*$F$2+G32*$G$2+H32*$H$2+I32*$I$2+K32)))) -> 4000000029 | F32: 4 | J32: =J31+1 -> 20000000029 | K32: 29
A33: ARL | B33: 6A6 | C33: ARL | D33: 1-1/2 D/C OFFSET NIPPLE | E33: =IF(F33="",J33,IF(G33="",F33*$F$2+K33,IF(H33="",F33*$F$2+G33*$G$2+K33,IF(I33="",F33*$F$2+G33*$G$2+H33*$H$2+K33,F33*$F$2+G33*$G$2+H33*$H$2+I33*$I$2+K33)))) -> 4000000030 | F33: 4 | J33: =J32+1 -> 20000000030 | K33: 30
A34: ARL | B34: 801 | C34: ARL | D34: 3/4 D/C SS EMT CONN | E34: =IF(F34="",J34,IF(G34="",F34*$F$2+K34,IF(H34="",F34*$F$2+G34*$G$2+K34,IF(I34="",F34*$F$2+G34*$G$2+H34*$H$2+K34,F34*$F$2+G34*$G$2+H34*$H$2+I34*$I$2+K34)))) -> 4000000031 | F34: 4 | J34: =J33+1 -> 20000000031 | K34: 31
A35: ARL | B35: 803 | C35: ARL | D35: 1-1/4 D/C SS EMT CONN | E35: =IF(F35="",J35,IF(G35="",F35*$F$2+K35,IF(H35="",F35*$F$2+G35*$G$2+K35,IF(I35="",F35*$F$2+G35*$G$2+H35*$H$2+K35,F35*$F$2+G35*$G$2+H35*$H$2+I35*$I$2+K35)))) -> 4000000032 | F35: 4 | J35: =J34+1 -> 20000000032 | K35: 32
A36: ARL | B36: 831RT | C36: ARL | D36: 3/4 EMT COMP CPLG | E36: =IF(F36="",J36,IF(G36="",F36*$F$2+K36,IF(H36="",F36*$F$2+G36*$G$2+K36,IF(I36="",F36*$F$2+G36*$G$2+H36*$H$2+K36,F36*$F$2+G36*$G$2+H36*$H$2+I36*$I$2+K36)))) -> 4000000033 | F36: 4 | J36: =J35+1 -> 20000000033 | K36: 33
A37: ARL | B37: 842ST | C37: ARL | D37: 3/4 SNPT SEU CONN | E37: =IF(F37="",J37,IF(G37="",F37*$F$2+K37,IF(H37="",F37*$F$2+G37*$G$2+K37,IF(I37="",F37*$F$2+G37*$G$2+H37*$H$2+K37,F37*$F$2+G37*$G$2+H37*$H$2+I37*$I$2+K37)))) -> 4000000034 | F37: 4 | J37: =J36+1 -> 20000000034 | K37: 34
A38: ARL | B38: 843S | C38: ARL | D38: 1-IN 2-SCR SEC CONN | E38: =IF(F38="",J38,IF(G38="",F38*$F$2+K38,IF(H38="",F38*$F$2+G38*$G$2+K38,IF(I38="",F38*$F$2+G38*$G$2+H38*$H$2+K38,F38*$F$2+G38*$G$2+H38*$H$2+I38*$I$2+K38)))) -> 4000000035 | F38: 4 | J38: =J37+1 -> 20000000035 | K38: 35
A39: ARL | B39: 862 | C39: ARL | D39: 3/4" EMT TO FLEX (25) [100] | E39: =IF(F39="",J39,IF(G39="",F39*$F$2+K39,IF(H39="",F39*$F$2+G39*$G$2+K39,IF(I39="",F39*$F$2+G39*$G$2+H39*$H$2+K39,F39*$F$2+G39*$G$2+H39*$H$2+I39*$I$2+K39)))) -> 4000000036 | F39: 4 | J39: =J38+1 -> 20000000036 | K39: 36
A40: ARL | B40: 8630 | C40: ARL | D40: 1" EMT TO FLEX CPLG (10) [40] | E40: =IF(F40="",J40,IF(G40="",F40*$F$2+K40,IF(H40="",F40*$F$2+G40*$G$2+K40,IF(I40="",F40*$F$2+G40*$G$2+H40*$H$2+K40,F40*$F$2+G40*$G$2+H40*$H$2+I40*$I$2+K40)))) -> 4000000037 | F40: 4 | J40: =J39+1 -> 20000000037 | K40: 37
A41: ARL | B41: 902 | C41: ARL | D41: 1-IN SNAP-IN KO BLANK | E41: =IF(F41="",J41,IF(G41="",F41*$F$2+K41,IF(H41="",F41*$F$2+G41*$G$2+K41,IF(I41="",F41*$F$2+G41*$G$2+H41*$H$2+K41,F41*$F$2+G41*$G$2+H41*$H$2+I41*$I$2+K41)))) -> 4000000038 | F41: 4 | J41: =J40+1 -> 20000000038 | K41: 38
A42: ARL | B42: 905 | C42: ARL | D42: 2-IN SNAP-IN KO BLANK | E42: =IF(F42="",J42,IF(G42="",F42*$F$2+K42,IF(H42="",F42*$F$2+G42*$G$2+K42,IF(I42="",F42*$F$2+G42*$G$2+H42*$H$2+K42,F42*$F$2+G42*$G$2+H42*$H$2+I42*$I$2+K42)))) -> 4000000039 | F42: 4 | J42: =J41+1 -> 20000000039 | K42: 39
A43: ARL | B43: 932NM | C43: ARL | D43: 1-IN PVC CONDUIT BODY | E43: =IF(F43="",J43,IF(G43="",F43*$F$2+K43,IF(H43="",F43*$F$2+G43*$G$2+K43,IF(I43="",F43*$F$2+G43*$G$2+H43*$H$2+K43,F43*$F$2+G43*$G$2+H43*$H$2+I43*$I$2+K43)))) -> 4000000040 | F43: 4 | J43: =J42+1 -> 20000000040 | K43: 40
A44: ARL | B44: DLN2 | C44: ARL | D44: 3/4 DIE CAST LOCKNUT | E44: =IF(F44="",J44,IF(G44="",F44*$F$2+K44,IF(H44="",F44*$F$2+G44*$G$2+K44,IF(I44="",F44*$F$2+G44*$G$2+H44*$H$2+K44,F44*$F$2+G44*$G$2+H44*$H$2+I44*$I$2+K44)))) -> 4000000041 | F44: 4 | J44: =J43+1 -> 20000000041 | K44: 41
A45: ARL | B45: EMT75 | C45: ARL | D45: 3/4IN NM TERMINATOR | E45: =IF(F45="",J45,IF(G45="",F45*$F$2+K45,IF(H45="",F45*$F$2+G45*$G$2+K45,IF(I45="",F45*$F$2+G45*$G$2+H45*$H$2+K45,F45*$F$2+G45*$G$2+H45*$H$2+I45*$I$2+K45)))) -> 4000000042 | F45: 4 | J45: =J44+1 -> 20000000042 | K45: 42
A46: ARL | B46: GF862 | C46: ARL | D46: 3/4 FLEX TO EMT COUPLING | E46: =IF(F46="",J46,IF(G46="",F46*$F$2+K46,IF(H46="",F46*$F$2+G46*$G$2+K46,IF(I46="",F46*$F$2+G46*$G$2+H46*$H$2+K46,F46*$F$2+G46*$G$2+H46*$H$2+I46*$I$2+K46)))) -> 4000000043 | F46: 4 | J46: =J45+1 -> 20000000043 | K46: 43
A47: ARL | B47: GF863 | C47: ARL | D47: 1-IN FLEX TO EMT COUPLING | E47: =IF(F47="",J47,IF(G47="",F47*$F$2+K47,IF(H47="",F47*$F$2+G47*$G$2+K47,IF(I47="",F47*$F$2+G47*$G$2+H47*$H$2+K47,F47*$F$2+G47*$G$2+H47*$H$2+I47*$I$2+K47)))) -> 4000000044 | F47: 4 | J47: =J46+1 -> 20000000044 | K47: 44
A48: ARL | B48: GFC75 | C48: ARL | D48: 3/4 D/C SCR-IN FLEX CPLG | E48: =IF(F48="",J48,IF(G48="",F48*$F$2+K48,IF(H48="",F48*$F$2+G48*$G$2+K48,IF(I48="",F48*$F$2+G48*$G$2+H48*$H$2+K48,F48*$F$2+G48*$G$2+H48*$H$2+I48*$I$2+K48)))) -> 4000000045 | F48: 4 | J48: =J47+1 -> 20000000045 | K48: 45
A49: ARL | B49: HL7500 | C49: ARL | D49: 3/4 SS EMT/RID ELL | E49: =IF(F49="",J49,IF(G49="",F49*$F$2+K49,IF(H49="",F49*$F$2+G49*$G$2+K49,IF(I49="",F49*$F$2+G49*$G$2+H49*$H$2+K49,F49*$F$2+G49*$G$2+H49*$H$2+I49*$I$2+K49)))) -> 4000000046 | F49: 4 | J49: =J48+1 -> 20000000046 | K49: 46
A50: ARL | B50: LPCG757 | C50: ARL | D50: 3/4 .375/.750 NMCRDCONN | E50: =IF(F50="",J50,IF(G50="",F50*$F$2+K50,IF(H50="",F50*$F$2+G50*$G$2+K50,IF(I50="",F50*$F$2+G50*$G$2+H50*$H$2+K50,F50*$F$2+G50*$G$2+H50*$H$2+I50*$I$2+K50)))) -> 4000000047 | F50: 4 | J50: =J49+1 -> 20000000047 | K50: 47
A51: ARL | B51: LT100 | C51: ARL | D51: 1-IN STR L/T FLEX CONN | E51: =IF(F51="",J51,IF(G51="",F51*$F$2+K51,IF(H51="",F51*$F$2+G51*$G$2+K51,IF(I51="",F51*$F$2+G51*$G$2+H51*$H$2+K51,F51*$F$2+G51*$G$2+H51*$H$2+I51*$I$2+K51)))) -> 4000000048 | F51: 4 | J51: =J50+1 -> 20000000048 | K51: 48
...

Sheet Worksheet
A1: Sequence | B1: MFR | C1: Catalog # | D1: Quantity
A2: =IFERROR(SMALL('Order Sheet'!A:A,1),"") -> 2000000944 | B2: =IF(A2="","",(VLOOKUP(A2,'Order Sheet'!A:B,2,FALSE))) -> QCELL | C2: =IF(A2="","",(VLOOKUP(A2,'Order Sheet'!A:C,3,FALSE))) -> Q.PEAK DUO BLK ML-G10+ 400 | D2: =IF(A2="","",(VLOOKUP(A2,'Order Sheet'!A:E,5,FALSE))) -> 15
A3: =IFERROR(SMALL('Order Sheet'!A:A,2),"") -> 4000000099 | B3: =IF(A3="","",(VLOOKUP(A3,'Order Sheet'!A:B,2,FALSE))) -> BPT | C3: =IF(A3="","",(VLOOKUP(A3,'Order Sheet'!A:C,3,FALSE))) -> 382DC | D3: =IF(A3="","",(VLOOKUP(A3,'Order Sheet'!A:E,5,FALSE))) -> 2
A4: =IFERROR(SMALL('Order Sheet'!A:A,3),"") -> 4000000118 | B4: =IF(A4="","",(VLOOKUP(A4,'Order Sheet'!A:B,2,FALSE))) -> BPT | C4: =IF(A4="","",(VLOOKUP(A4,'Order Sheet'!A:C,3,FALSE))) -> SR075 | D4: =IF(A4="","",(VLOOKUP(A4,'Order Sheet'!A:E,5,FALSE))) -> 5
A5: =IFERROR(SMALL('Order Sheet'!A:A,4),"") -> 4000000143 | B5: =IF(A5="","",(VLOOKUP(A5,'Order Sheet'!A:B,2,FALSE))) -> CHEML | C5: =IF(A5="","",(VLOOKUP(A5,'Order Sheet'!A:C,3,FALSE))) -> F1270GR | D5: =IF(A5="","",(VLOOKUP(A5,'Order Sheet'!A:E,5,FALSE))) -> 1
A6: =IFERROR(SMALL('Order Sheet'!A:A,5),"") -> 4000001225 | B6: =IF(A6="","",(VLOOKUP(A6,'Order Sheet'!A:B,2,FALSE))) -> SWIRE | C6: =IF(A6="","",(VLOOKUP(A6,'Order Sheet'!A:C,3,FALSE))) -> 282 | D6: =IF(A6="","",(VLOOKUP(A6,'Order Sheet'!A:E,5,FALSE))) -> 5
A7: =IFERROR(SMALL('Order Sheet'!A:A,6),"") -> 4000001234 | B7: =IF(A7="","",(VLOOKUP(A7,'Order Sheet'!A:B,2,FALSE))) -> SWIRE | C7: =IF(A7="","",(VLOOKUP(A7,'Order Sheet'!A:C,3,FALSE))) -> 452TZ | D7: =IF(A7="","",(VLOOKUP(A7,'Order Sheet'!A:E,5,FALSE))) -> 4
A8: =IFERROR(SMALL('Order Sheet'!A:A,7),"") -> 4000001283 | B8: =IF(A8="","",(VLOOKUP(A8,'Order Sheet'!A:B,2,FALSE))) -> SWIRE | C8: =IF(A8="","",(VLOOKUP(A8,'Order Sheet'!A:C,3,FALSE))) -> 832TZ | D8: =IF(A8="","",(VLOOKUP(A8,'Order Sheet'!A:E,5,FALSE))) -> 5
A9: =IFERROR(SMALL('Order Sheet'!A:A,8),"") -> 6000000196 | B9: =IF(A9="","",(VLOOKUP(A9,'Order Sheet'!A:B,2,FALSE))) -> EATON | C9: =IF(A9="","",(VLOOKUP(A9,'Order Sheet'!A:C,3,FALSE))) -> BR220 | D9: =IF(A9="","",(VLOOKUP(A9,'Order Sheet'!A:E,5,FALSE))) -> 2
A10: =IFERROR(SMALL('Order Sheet'!A:A,9),"") -> 6000000248 | B10: =IF(A10="","",(VLOOKUP(A10,'Order Sheet'!A:B,2,FALSE))) -> EATON | C10: =IF(A10="","",(VLOOKUP(A10,'Order Sheet'!A:C,3,FALSE))) -> DG222URB | D10: =IF(A10="","",(VLOOKUP(A10,'Order Sheet'!A:E,5,FALSE))) -> 1
A11: =IFERROR(SMALL('Order Sheet'!A:A,10),"") -> 6000000358 | B11: =IF(A11="","",(VLOOKUP(A11,'Order Sheet'!A:B,2,FALSE))) -> EZSLR | C11: =IF(A11="","",(VLOOKUP(A11,'Order Sheet'!A:C,3,FALSE))) -> JB-1.2 | D11: =IF(A11="","",(VLOOKUP(A11,'Order Sheet'!A:E,5,FALSE))) -> 1
A12: =IFERROR(SMALL('Order Sheet'!A:A,11),"") -> 6000000373 | B12: =IF(A12="","",(VLOOKUP(A12,'Order Sheet'!A:B,2,FALSE))) -> FLEX | C12: =IF(A12="","",(VLOOKUP(A12,'Order Sheet'!A:C,3,FALSE))) -> RWA-3/4 | D12: =IF(A12="","",(VLOOKUP(A12,'Order Sheet'!A:E,5,FALSE))) -> 100
A13: =IFERROR(SMALL('Order Sheet'!A:A,12),"") -> 6000000737 | B13: =IF(A13="","",(VLOOKUP(A13,'Order Sheet'!A:B,2,FALSE))) -> NSI | C13: =IF(A13="","",(VLOOKUP(A13,'Order Sheet'!A:C,3,FALSE))) -> 11500 | D13: =IF(A13="","",(VLOOKUP(A13,'Order Sheet'!A:E,5,FALSE))) -> 1
A14: =IFERROR(SMALL('Order Sheet'!A:A,13),"") -> 6000000789 | B14: =IF(A14="","",(VLOOKUP(A14,'Order Sheet'!A:B,2,FALSE))) -> PVC | C14: =IF(A14="","",(VLOOKUP(A14,'Order Sheet'!A:C,3,FALSE))) -> COND-3/4 | D14: =IF(A14="","",(VLOOKUP(A14,'Order Sheet'!A:E,5,FALSE))) -> 1
A15: =IFERROR(SMALL('Order Sheet'!A:A,14),"") -> 6000000806 | B15: =IF(A15="","",(VLOOKUP(A15,'Order Sheet'!A:B,2,FALSE))) -> PVC | C15: =IF(A15="","",(VLOOKUP(A15,'Order Sheet'!A:C,3,FALSE))) -> EL-3/4 | D15: =IF(A15="","",(VLOOKUP(A15,'Order Sheet'!A:E,5,FALSE))) -> 1
A16: =IFERROR(SMALL('Order Sheet'!A:A,15),"") -> 6000000824 | B16: =IF(A16="","",(VLOOKUP(A16,'Order Sheet'!A:B,2,FALSE))) -> PVC | C16: =IF(A16="","",(VLOOKUP(A16,'Order Sheet'!A:C,3,FALSE))) -> FA-3/4 | D16: =IF(A16="","",(VLOOKUP(A16,'Order Sheet'!A:E,5,FALSE))) -> 1
A17: =IFERROR(SMALL('Order Sheet'!A:A,16),"") -> 6000000842 | B17: =IF(A17="","",(VLOOKUP(A17,'Order Sheet'!A:B,2,FALSE))) -> PVC | C17: =IF(A17="","",(VLOOKUP(A17,'Order Sheet'!A:C,3,FALSE))) -> LL-3/4 | D17: =IF(A17="","",(VLOOKUP(A17,'Order Sheet'!A:E,5,FALSE))) -> 1
A18: =IFERROR(SMALL('Order Sheet'!A:A,17),"") -> 6000000854 | B18: =IF(A18="","",(VLOOKUP(A18,'Order Sheet'!A:B,2,FALSE))) -> PVC | C18: =IF(A18="","",(VLOOKUP(A18,'Order Sheet'!A:C,3,FALSE))) -> TA-3/4 | D18: =IF(A18="","",(VLOOKUP(A18,'Order Sheet'!A:E,5,FALSE))) -> 5
A19: =IFERROR(SMALL('Order Sheet'!A:A,18),"") -> 6000001039 | B19: =IF(A19="","",(VLOOKUP(A19,'Order Sheet'!A:B,2,FALSE))) -> SOLAD | C19: =IF(A19="","",(VLOOKUP(A19,'Order Sheet'!A:C,3,FALSE))) -> 1604 | D19: =IF(A19="","",(VLOOKUP(A19,'Order Sheet'!A:E,5,FALSE))) -> 1
A20: =IFERROR(SMALL('Order Sheet'!A:A,19),"") -> 6000001041 | B20: =IF(A20="","",(VLOOKUP(A20,'Order Sheet'!A:B,2,FALSE))) -> SOLAD | C20: =IF(A20="","",(VLOOKUP(A20,'Order Sheet'!A:C,3,FALSE))) -> 0799-5B | D20: =IF(A20="","",(VLOOKUP(A20,'Order Sheet'!A:E,5,FALSE))) -> 1
A21: =IFERROR(SMALL('Order Sheet'!A:A,20),"") -> 6000001132 | B21: =IF(A21="","",(VLOOKUP(A21,'Order Sheet'!A:B,2,FALSE))) -> SQD | C21: =IF(A21="","",(VLOOKUP(A21,'Order Sheet'!A:C,3,FALSE))) -> QO230 | D21: =IF(A21="","",(VLOOKUP(A21,'Order Sheet'!A:E,5,FALSE))) -> 1
A22: =IFERROR(SMALL('Order Sheet'!A:A,21),"") -> 6000001142 | B22: =IF(A22="","",(VLOOKUP(A22,'Order Sheet'!A:B,2,FALSE))) -> SQD | C22: =IF(A22="","",(VLOOKUP(A22,'Order Sheet'!A:C,3,FALSE))) -> QOM2150VH | D22: =IF(A22="","",(VLOOKUP(A22,'Order Sheet'!A:E,5,FALSE))) -> 1
A23: =IFERROR(SMALL('Order Sheet'!A:A,22),"") | B23: =IF(A23="","",(VLOOKUP(A23,'Order Sheet'!A:B,2,FALSE))) | C23: =IF(A23="","",(VLOOKUP(A23,'Order Sheet'!A:C,3,FALSE))) | D23: =IF(A23="","",(VLOOKUP(A23,'Order Sheet'!A:E,5,FALSE)))
A24: =IFERROR(SMALL('Order Sheet'!A:A,23),"") | B24: =IF(A24="","",(VLOOKUP(A24,'Order Sheet'!A:B,2,FALSE))) | C24: =IF(A24="","",(VLOOKUP(A24,'Order Sheet'!A:C,3,FALSE))) | D24: =IF(A24="","",(VLOOKUP(A24,'Order Sheet'!A:E,5,FALSE)))
A25: =IFERROR(SMALL('Order Sheet'!A:A,24),"") | B25: =IF(A25="","",(VLOOKUP(A25,'Order Sheet'!A:B,2,FALSE))) | C25: =IF(A25="","",(VLOOKUP(A25,'Order Sheet'!A:C,3,FALSE))) | D25: =IF(A25="","",(VLOOKUP(A25,'Order Sheet'!A:E,5,FALSE)))
A26: =IFERROR(SMALL('Order Sheet'!A:A,25),"") | B26: =IF(A26="","",(VLOOKUP(A26,'Order Sheet'!A:B,2,FALSE))) | C26: =IF(A26="","",(VLOOKUP(A26,'Order Sheet'!A:C,3,FALSE))) | D26: =IF(A26="","",(VLOOKUP(A26,'Order Sheet'!A:E,5,FALSE)))
A27: =IFERROR(SMALL('Order Sheet'!A:A,26),"") | B27: =IF(A27="","",(VLOOKUP(A27,'Order Sheet'!A:B,2,FALSE))) | C27: =IF(A27="","",(VLOOKUP(A27,'Order Sheet'!A:C,3,FALSE))) | D27: =IF(A27="","",(VLOOKUP(A27,'Order Sheet'!A:E,5,FALSE)))
A28: =IFERROR(SMALL('Order Sheet'!A:A,27),"") | B28: =IF(A28="","",(VLOOKUP(A28,'Order Sheet'!A:B,2,FALSE))) | C28: =IF(A28="","",(VLOOKUP(A28,'Order Sheet'!A:C,3,FALSE))) | D28: =IF(A28="","",(VLOOKUP(A28,'Order Sheet'!A:E,5,FALSE)))
A29: =IFERROR(SMALL('Order Sheet'!A:A,28),"") | B29: =IF(A29="","",(VLOOKUP(A29,'Order Sheet'!A:B,2,FALSE))) | C29: =IF(A29="","",(VLOOKUP(A29,'Order Sheet'!A:C,3,FALSE))) | D29: =IF(A29="","",(VLOOKUP(A29,'Order Sheet'!A:E,5,FALSE)))
A30: =IFERROR(SMALL('Order Sheet'!A:A,29),"") | B30: =IF(A30="","",(VLOOKUP(A30,'Order Sheet'!A:B,2,FALSE))) | C30: =IF(A30="","",(VLOOKUP(A30,'Order Sheet'!A:C,3,FALSE))) | D30: =IF(A30="","",(VLOOKUP(A30,'Order Sheet'!A:E,5,FALSE)))
A31: =IFERROR(SMALL('Order Sheet'!A:A,30),"") | B31: =IF(A31="","",(VLOOKUP(A31,'Order Sheet'!A:B,2,FALSE))) | C31: =IF(A31="","",(VLOOKUP(A31,'Order Sheet'!A:C,3,FALSE))) | D31: =IF(A31="","",(VLOOKUP(A31,'Order Sheet'!A:E,5,FALSE)))
A32: =IFERROR(SMALL('Order Sheet'!A:A,31),"") | B32: =IF(A32="","",(VLOOKUP(A32,'Order Sheet'!A:B,2,FALSE))) | C32: =IF(A32="","",(VLOOKUP(A32,'Order Sheet'!A:C,3,FALSE))) | D32: =IF(A32="","",(VLOOKUP(A32,'Order Sheet'!A:E,5,FALSE)))
A33: =IFERROR(SMALL('Order Sheet'!A:A,32),"") | B33: =IF(A33="","",(VLOOKUP(A33,'Order Sheet'!A:B,2,FALSE))) | C33: =IF(A33="","",(VLOOKUP(A33,'Order Sheet'!A:C,3,FALSE))) | D33: =IF(A33="","",(VLOOKUP(A33,'Order Sheet'!A:E,5,FALSE)))
A34: =IFERROR(SMALL('Order Sheet'!A:A,33),"") | B34: =IF(A34="","",(VLOOKUP(A34,'Order Sheet'!A:B,2,FALSE))) | C34: =IF(A34="","",(VLOOKUP(A34,'Order Sheet'!A:C,3,FALSE))) | D34: =IF(A34="","",(VLOOKUP(A34,'Order Sheet'!A:E,5,FALSE)))
A35: =IFERROR(SMALL('Order Sheet'!A:A,34),"") | B35: =IF(A35="","",(VLOOKUP(A35,'Order Sheet'!A:B,2,FALSE))) | C35: =IF(A35="","",(VLOOKUP(A35,'Order Sheet'!A:C,3,FALSE))) | D35: =IF(A35="","",(VLOOKUP(A35,'Order Sheet'!A:E,5,FALSE)))
A36: =IFERROR(SMALL('Order Sheet'!A:A,35),"") | B36: =IF(A36="","",(VLOOKUP(A36,'Order Sheet'!A:B,2,FALSE))) | C36: =IF(A36="","",(VLOOKUP(A36,'Order Sheet'!A:C,3,FALSE))) | D36: =IF(A36="","",(VLOOKUP(A36,'Order Sheet'!A:E,5,FALSE)))
A37: =IFERROR(SMALL('Order Sheet'!A:A,36),"") | B37: =IF(A37="","",(VLOOKUP(A37,'Order Sheet'!A:B,2,FALSE))) | C37: =IF(A37="","",(VLOOKUP(A37,'Order Sheet'!A:C,3,FALSE))) | D37: =IF(A37="","",(VLOOKUP(A37,'Order Sheet'!A:E,5,FALSE)))
A38: =IFERROR(SMALL('Order Sheet'!A:A,37),"") | B38: =IF(A38="","",(VLOOKUP(A38,'Order Sheet'!A:B,2,FALSE))) | C38: =IF(A38="","",(VLOOKUP(A38,'Order Sheet'!A:C,3,FALSE))) | D38: =IF(A38="","",(VLOOKUP(A38,'Order Sheet'!A:E,5,FALSE)))
A39: =IFERROR(SMALL('Order Sheet'!A:A,38),"") | B39: =IF(A39="","",(VLOOKUP(A39,'Order Sheet'!A:B,2,FALSE))) | C39: =IF(A39="","",(VLOOKUP(A39,'Order Sheet'!A:C,3,FALSE))) | D39: =IF(A39="","",(VLOOKUP(A39,'Order Sheet'!A:E,5,FALSE)))
A40: =IFERROR(SMALL('Order Sheet'!A:A,39),"") | B40: =IF(A40="","",(VLOOKUP(A40,'Order Sheet'!A:B,2,FALSE))) | C40: =IF(A40="","",(VLOOKUP(A40,'Order Sheet'!A:C,3,FALSE))) | D40: =IF(A40="","",(VLOOKUP(A40,'Order Sheet'!A:E,5,FALSE)))
...
